Workbook

Sheet Cover
A1: Karur Vysya Bank - Initiating Coverage Model
A2: Prepared by Gaurav Waghmode | Price date 30-Sep-2026 | Student research exercise - not investment advice; author is not SEBI-registered
A4: CMP (Rs) | B4: =Valuation!B4 -> 325
A5: 12-month target (Rs) | B5: =Valuation!B36 -> 300.07135
A6: Upside / (downside) | B6: =Valuation!B37 -> -0.076703547
A7: Rating | B7: =Valuation!B38 -> HOLD
A8: Cost of equity | B8: =Valuation!B8 -> 0.136
A9: Justified P/ABV | B9: =Valuation!B13 -> 1.6271813
A10: FY27E EPS (Rs) | B10: =Model!G71 -> 30.980287
A11: FY28E ROE | B11: =Model!H62 -> 0.17108092
A12: FY28E ROA | B12: =Model!H60 -> 0.018191809
A13: Scenario running | B13: =CHOOSE(Model!B3,"Bear","Base","Bull") -> Base
A16: HOW TO USE
A17: 1. Change yellow cells on 'Model' (forecast drivers) and 'Valuation' (Ke, g, weights). Everything else recalculates.
A18: 2. Flip the scenario switch at Model!B3 (1 Bear / 2 Base / 3 Bull).
A19: 3. After each quarterly result, paste the new quarter into 'Quarterly' and re-check the FY27E drivers.
A21: COLOUR CODE: blue text = hard-coded input | black = formula | green = link to another sheet | yellow fill = key assumption
A23: SOURCES
A24: Screener.in company page (P&L, balance sheet, quarterly results, GNPA/NNPA), fetched 30-Sep-2026.
A25: KVB Q4FY26 earnings call transcript (7-May-2026): FY26 operating profit, opex growth, provisions detail, NIM, CRAR 18.76%, FY27 guidance.
A26: KVB FY24 Directors report: FY23-24 advances, operating profit, CASA. MarketsMojo/C-MOTS: GNPA/NNPA amounts, PCR history.
A27: Q1FY27 results coverage (Kotak Neo, PSU Connect, Angel One): NIM 4.26%, ROA 2.11%, ROE 20.24%, cost-to-income 41.79%, PCR 96.21%, CASA Rs33,777cr.
A28: Trading Economics: India 10Y G-sec ~7.1% (15-Sep-2026). Business Standard (May-2022): FY22 operating profit Rs1,630cr.
A29: VERIFY every blue number against the annual report before you use this model in an interview.

Sheet Model
A1: Karur Vysya Bank (NSE: KARURVYSYA) - Operating model
A2: Standalone. History from company filings/Screener; FY27E-FY29E are analyst estimates. Blue = input, black = formula, green = link, yellow = key assumption.
A3: Scenario switch (1 Bear, 2 Base, 3 Bull) | B3: 2
B4: Bear | C4: Base | D4: Bull | E4: Active
A5: Loan & deposit growth delta | B5: -0.04 | C5: 0 | D5: 0.02 | E5: =CHOOSE($B$3,B5,C5,D5) -> 0 | G5: Capital / net worth (Tier1+2 factor) | I5: 1.03
A6: Yield on earning assets delta | B6: -0.0015 | C6: 0 | D6: 0.001 | E6: =CHOOSE($B$3,B6,C6,D6) -> 0 | G6: Fixed assets growth (forecast) | I6: 0.08
A7: Credit cost delta | B7: 0.003 | C7: 0 | D7: -0.001 | E7: =CHOOSE($B$3,B7,C7,D7) -> 0
A8: Write-off recoveries multiplier | B8: 0.6 | C8: 1 | D8: 1.2 | E8: =CHOOSE($B$3,B8,C8,D8) -> 1
A10: INR crore unless stated | B10: FY22 | C10: FY23 | D10: FY24 | E10: FY25 | F10: FY26 | G10: FY27E | H10: FY28E | I10: FY29E | J10: Source / comment
A11: BALANCE SHEET
A12: Advances (gross) | B12: 57568 | C12: 64168 | D12: 74423 | E12: 84491 | F12: 98754 | G12: =F12*(1+G13+$E$5) -> 115542.18 | H12: =G12*(1+H13+$E$5) -> 134028.93 | I12: =H12*(1+I13+$E$5) -> 154133.27 | J12: FY23-26: company (Directors report, Q4 call). FY22 derived: GNPA Rs3,431cr / 5.96%.
A13: Advances growth (base input; scenario delta added) | C13: =C12/B12-1 -> 0.11464703 | D13: =D12/C12-1 -> 0.15981486 | E13: =E12/D12-1 -> 0.13528076 | F13: =F12/E12-1 -> 0.16881088 | G13: 0.17 | H13: 0.16 | I13: 0.15 | J13: Mgmt: credit growth 1-2% above industry (Q4FY26 call); Q1FY27 +17.1% YoY.
A14: Deposits | B14: 68486 | C14: 76638 | D14: 89113 | E14: 102078 | F14: 115666 | G14: =F14*(1+G15+$E$5) -> 134172.56 | H14: =G14*(1+H15+$E$5) -> 154969.31 | I14: =H14*(1+I15+$E$5) -> 178214.7 | J14: Screener balance sheet; Q1FY27 Rs1,22,587cr (+14.9% YoY).
A15: Deposit growth | C15: =C14/B14-1 -> 0.11903163 | D15: =D14/C14-1 -> 0.16277826 | E15: =E14/D14-1 -> 0.14548943 | F15: =F14/E14-1 -> 0.13311389 | G15: 0.16 | H15: 0.155 | I15: 0.15
A16: Investments | B16: 17216 | C16: 18808 | D16: 22344 | E16: 23831 | F16: 29020 | G16: =G14*G17 -> 33543.14 | H16: =H14*H17 -> 38742.327 | I16: =I14*I17 -> 44553.676
A17: Investments / deposits | B17: =B16/B14 -> 0.25137984 | C17: =C16/C14 -> 0.2454135 | D17: =D16/D14 -> 0.25073783 | E17: =E16/E14 -> 0.23345873 | F17: =F16/F14 -> 0.25089482 | G17: 0.25 | H17: 0.25 | I17: 0.25
A18: Borrowings | B18: 1339 | C18: 1432 | D18: 2478 | E18: 1217 | F18: 2623 | G18: =G14*G19 -> 2951.7963 | H18: =H14*H19 -> 3409.3247 | I18: =I14*I19 -> 3920.7235
A19: Borrowings / deposits | B19: =B18/B14 -> 0.019551441 | C19: =C18/C14 -> 0.018685248 | D19: =D18/D14 -> 0.027807391 | E19: =E18/E14 -> 0.011922256 | F19: =F18/F14 -> 0.022677364 | G19: 0.022 | H19: 0.022 | I19: 0.022
A20: Other liabilities & provisions | B20: 2650 | C20: 3526 | D20: 3822 | E20: 4143 | F20: 4207 | G20: =G14*G21 -> 4830.2122 | H20: =H14*H21 -> 5578.895 | I20: =I14*I21 -> 6415.7293
A21: Other liabilities / deposits | B21: =B20/B14 -> 0.03869404 | C21: =C20/C14 -> 0.046008508 | D21: =D20/D14 -> 0.042889365 | E21: =E20/E14 -> 0.04058661 | F21: =F20/F14 -> 0.036371968 | G21: 0.036 | H21: 0.036 | I21: 0.036
A22: Net worth (equity + reserves) | B22: 7596 | C22: 8584 | D22: 10040 | E22: 11930 | F22: 14108 | G22: =F22+G45-G47 -> 16798.638 | H22: =G22+H45-H47 -> 19600.909 | I22: =H22+I45-I47 -> 22742.868 | J22: Forecast: opening + PAT - dividends (no equity raise; mgmt: no capital need in FY27).
A23: Total liabilities & equity | B23: =B14+B18+B20+B22 -> 80071 | C23: =C14+C18+C20+C22 -> 90180 | D23: =D14+D18+D20+D22 -> 105453 | E23: =E14+E18+E20+E22 -> 119368 | F23: =F14+F18+F20+F22 -> 136604 | G23: =G14+G18+G20+G22 -> 158753.21 | H23: =H14+H18+H20+H22 -> 183558.44 | I23: =I14+I18+I20+I22 -> 211294.02
A24: Fixed assets incl. CWIP | B24: 479 | C24: 435 | D24: 432 | E24: 490 | F24: 502 | G24: =F24*(1+$I$6) -> 542.16 | H24: =G24*(1+$I$6) -> 585.5328 | I24: =H24*(1+$I$6) -> 632.37542
A25: Cash, RBI balances & other assets (plug) | B25: =B23-B12-B16-B24 -> 4808 | C25: =C23-C12-C16-C24 -> 6769 | D25: =D23-D12-D16-D24 -> 8254 | E25: =E23-E12-E16-E24 -> 10556 | F25: =F23-F12-F16-F24 -> 8328 | G25: =G23-G12-G16-G24 -> 9125.7264 | H25: =H23-H12-H16-H24 -> 10201.647 | I25: =I23-I12-I16-I24 -> 11974.704 | J25: Balancing item. History derived so the sheet balances (reported totals differ by <=1 from rounding).
A26: Total assets | B26: =B12+B16+B24+B25 -> 80071 | C26: =C12+C16+C24+C25 -> 90180 | D26: =D12+D16+D24+D25 -> 105453 | E26: =E12+E16+E24+E25 -> 119368 | F26: =F12+F16+F24+F25 -> 136604 | G26: =G12+G16+G24+G25 -> 158753.21 | H26: =H12+H16+H24+H25 -> 183558.44 | I26: =I12+I16+I24+I25 -> 211294.02
A27: Check: assets - liabilities (must be 0) | B27: =B26-B23 -> 0 | C27: =C26-C23 -> 0 | D27: =D26-D23 -> 0 | E27: =E26-E23 -> 0 | F27: =F26-F23 -> 0 | G27: =G26-G23 -> 0 | H27: =H26-H23 -> 0 | I27: =I26-I23 -> 0
A28: PROFIT & LOSS
A29: Interest earned | B29: 5588 | C29: 6517 | D29: 8213 | E29: 9678 | F29: 11074 | G29: =G51*G49 -> 12984.702 | H29: =H51*H49 -> 15014.609 | I29: =I51*I49 -> 17235.66 | J29: Screener P&L (C-MOTS). Forecast = yield x avg earning assets.
A30: Interest expended | B30: 2872 | C30: 3168 | D30: 4395 | E30: 5418 | F30: 6136 | G30: =G53*G52 -> 7215.4273 | H30: =H53*H52 -> 8451.3855 | I30: =I53*I52 -> 9738.7021
A31: Net interest income (NII) | B31: =B29-B30 -> 2716 | C31: =C29-C30 -> 3349 | D31: =D29-D30 -> 3818 | E31: =E29-E30 -> 4260 | F31: =F29-F30 -> 4938 | G31: =G29-G30 -> 5769.2748 | H31: =H29-H30 -> 6563.2238 | I31: =I29-I30 -> 7496.9584
A32: Core other income (fees, treasury, other) | B32: 769 | C32: 1159 | D32: 1649 | E32: 1192 | F32: 1405 | G32: =F32*(1+G33) -> 1615.75 | H32: =G32*(1+H33) -> 1858.1125 | I32: =H32*(1+I33) -> 2118.2483 | J32: FY25-26 = total other income less write-off recoveries (Rs638cr / Rs679cr per Q4FY26 call). FY22-24 recoveries not split out.
A33: Core other income growth | C33: =C32/B32-1 -> 0.50715215 | D33: =D32/C32-1 -> 0.42277826 | E33: =E32/D32-1 -> -0.27713766 | F33: =F32/E32-1 -> 0.17869128 | G33: 0.15 | H33: 0.15 | I33: 0.14
A34: Write-off recoveries - base input | G34: 550 | H34: 400 | I34: 300 | J34: Key call: recoveries fade as the written-off pool is used up (mgmt: "perennially we cannot have write-off recovery").
A35: Recoveries from written-off accounts | E35: 638 | F35: 679 | G35: =G34*$E$8 -> 550 | H35: =H34*$E$8 -> 400 | I35: =I34*$E$8 -> 300
A36: Total other income | B36: =B32+B35 -> 769 | C36: =C32+C35 -> 1159 | D36: =D32+D35 -> 1649 | E36: =E32+E35 -> 1830 | F36: =F32+F35 -> 2084 | G36: =G32+G35 -> 2165.75 | H36: =H32+H35 -> 2258.1125 | I36: =I32+I35 -> 2418.2483
A37: Total income (NII + other income) | B37: =B31+B36 -> 3485 | C37: =C31+C36 -> 4508 | D37: =D31+D36 -> 5467 | E37: =E31+E36 -> 6090 | F37: =F31+F36 -> 7022 | G37: =G31+G36 -> 7935.0248 | H37: =H31+H36 -> 8821.3363 | I37: =I31+I36 -> 9915.2066
A38: Operating expenses | B38: 1855 | C38: 2032 | D38: 2638 | E38: 2877 | F38: 2947 | G38: =F38*(1+G39) -> 3359.58 | H38: =G38*(1+H39) -> 3796.3254 | I38: =H38*(1+I39) -> 4251.8844 | J38: Total income less reported operating profit (FY22 Rs1,630cr; FY23 Rs2,476cr; FY24 Rs2,829cr; FY26 Rs4,075cr, +26.85% YoY).
A39: Opex growth | C39: =C38/B38-1 -> 0.09541779 | D39: =D38/C38-1 -> 0.29822835 | E39: =E38/D38-1 -> 0.090598939 | F39: =F38/E38-1 -> 0.0243309 | G39: 0.14 | H39: 0.13 | I39: 0.12 | J39: 50 new branches in FY27, wage revision due; FY26 growth flattered by pension discount-rate gain.
A40: Pre-provision operating profit (PPOP) | B40: =B37-B38 -> 1630 | C40: =C37-C38 -> 2476 | D40: =D37-D38 -> 2829 | E40: =E37-E38 -> 3213 | F40: =F37-F38 -> 4075 | G40: =G37-G38 -> 4575.4448 | H40: =H37-H38 -> 5025.0109 | I40: =I37-I38 -> 5663.3222
A41: Provisions & contingencies | B41: 699 | C41: 1039 | D41: 729 | E41: 622 | F41: 755 | G41: =(G57+$E$7)*G56 -> 589.31449 | H41: =(H57+$E$7)*H56 -> 873.49888 | I41: =(I57+$E$7)*I56 -> 1008.5677 | J41: PPOP less PBT. FY26 includes Rs163cr one-time prudential provision (West Asia).
...

Sheet Valuation
A1: Valuation - Karur Vysya Bank
A2: Price date: 30-Sep-2026. Target horizon: 12 months (Sep-2027).
F3: SENSITIVITY 1: P/ABV fair value (Rs) - Ke (rows) x g (columns)
A4: CMP (Rs) | B4: 325 | C4: Screener, close 30-Sep-2026 | G4: 0.075 | H4: 0.08 | I4: 0.085 | J4: 0.09 | K4: 0.095
A5: Risk-free rate (10Y G-sec) | B5: 0.071 | C5: ~7.1% mid-Sep 2026 (four-month high; Trading Economics) | F5: 0.126 | G5: =($B$12-G$4)/($F5-G$4)*$B$16 -> 337.91779 | H5: =($B$12-H$4)/($F5-H$4)*$B$16 -> 354.50264 | I5: =($B$12-I$4)/($F5-I$4)*$B$16 -> 375.13258 | J5: =($B$12-J$4)/($F5-J$4)*$B$16 -> 401.49305 | K5: =($B$12-K$4)/($F5-K$4)*$B$16 -> 436.3569
A6: Beta | B6: 1 | C6: Assumption: mid-size private bank vs Nifty; test in sensitivity | F6: 0.131 | G6: =($B$12-G$4)/($F6-G$4)*$B$16 -> 307.74656 | H6: =($B$12-H$4)/($F6-H$4)*$B$16 -> 319.74748 | I6: =($B$12-I$4)/($F6-I$4)*$B$16 -> 334.3573 | J6: =($B$12-J$4)/($F6-J$4)*$B$16 -> 352.53048 | K6: =($B$12-K$4)/($F6-K$4)*$B$16 -> 375.75178
A7: Equity risk premium | B7: 0.065 | C7: Assumption (Indian broker range 5-7%) | F7: 0.136 | G7: =($B$12-G$4)/($F7-G$4)*$B$16 -> 282.52143 | H7: =($B$12-H$4)/($F7-H$4)*$B$16 -> 291.1986 | I7: =($B$12-I$4)/($F7-I$4)*$B$16 -> 301.57717 | J7: =($B$12-J$4)/($F7-J$4)*$B$16 -> 314.21195 | K7: =($B$12-K$4)/($F7-K$4)*$B$16 -> 329.92839
A8: Cost of equity (CAPM) = Rf + Beta x ERP | B8: =B5+B6*B7 -> 0.136 | F8: 0.141 | G8: =($B$12-G$4)/($F8-G$4)*$B$16 -> 261.11829 | H8: =($B$12-H$4)/($F8-H$4)*$B$16 -> 267.32986 | I8: =($B$12-I$4)/($F8-I$4)*$B$16 -> 274.65064 | J8: =($B$12-J$4)/($F8-J$4)*$B$16 -> 283.40686 | K8: =($B$12-K$4)/($F8-K$4)*$B$16 -> 294.06661
A9: Long-term growth (g) | B9: 0.085 | C9: Nominal GDP-like growth; must stay below Ke | F9: 0.146 | G9: =($B$12-G$4)/($F9-G$4)*$B$16 -> 242.72968 | H9: =($B$12-H$4)/($F9-H$4)*$B$16 -> 247.0776 | I9: =($B$12-I$4)/($F9-I$4)*$B$16 -> 252.13829 | J9: =($B$12-J$4)/($F9-J$4)*$B$16 -> 258.10267 | K9: =($B$12-K$4)/($F9-K$4)*$B$16 -> 265.23655
A11: METHOD 1: Justified P/ABV (Gordon growth) | F11: SENSITIVITY 2: P/ABV fair value (Rs) - change in NIM (rows, bps) x change in credit cost (cols, bps)
A12: Sustainable ROE (avg FY28E-FY29E) | B12: =AVERAGE(Model!H62,Model!I62) -> 0.16798625 | F12: First-order: holds FY28E balance sheet constant; ROE shift = (dNIM x EA/NW - dCC x Adv/NW) x (1 - tax)
A13: Justified P/ABV = (ROE - g) / (Ke - g) | B13: =(B12-B9)/(B8-B9) -> 1.6271813 | G13: -20 | H13: -10 | I13: 0 | J13: 15 | K13: 30
A14: ABVPS FY27E (Rs) | B14: =Model!G73 -> 171.44503 | F14: -30 | G14: =(($B$12+($F14/10000*Model!H49/Model!H61-G$13/10000*Model!H56/Model!H61)*(1-Model!H44))-$B$9)/($B$8-$B$9)*$B$16 -> 266.65174 | H14: =(($B$12+($F14/10000*Model!H49/Model!H61-H$13/10000*Model!H56/Model!H61)*(1-Model!H44))-$B$9)/($B$8-$B$9)*$B$16 -> 247.96421 | I14: =(($B$12+($F14/10000*Model!H49/Model!H61-I$13/10000*Model!H56/Model!H61)*(1-Model!H44))-$B$9)/($B$8-$B$9)*$B$16 -> 229.27667 | J14: =(($B$12+($F14/10000*Model!H49/Model!H61-J$13/10000*Model!H56/Model!H61)*(1-Model!H44))-$B$9)/($B$8-$B$9)*$B$16 -> 201.24538 | K14: =(($B$12+($F14/10000*Model!H49/Model!H61-K$13/10000*Model!H56/Model!H61)*(1-Model!H44))-$B$9)/($B$8-$B$9)*$B$16 -> 173.21408
A15: ABVPS FY28E (Rs) | B15: =Model!H73 -> 199.2293 | F15: -20 | G15: =(($B$12+($F15/10000*Model!H49/Model!H61-G$13/10000*Model!H56/Model!H61)*(1-Model!H44))-$B$9)/($B$8-$B$9)*$B$16 -> 290.7519 | H15: =(($B$12+($F15/10000*Model!H49/Model!H61-H$13/10000*Model!H56/Model!H61)*(1-Model!H44))-$B$9)/($B$8-$B$9)*$B$16 -> 272.06437 | I15: =(($B$12+($F15/10000*Model!H49/Model!H61-I$13/10000*Model!H56/Model!H61)*(1-Model!H44))-$B$9)/($B$8-$B$9)*$B$16 -> 253.37684 | J15: =(($B$12+($F15/10000*Model!H49/Model!H61-J$13/10000*Model!H56/Model!H61)*(1-Model!H44))-$B$9)/($B$8-$B$9)*$B$16 -> 225.34554 | K15: =(($B$12+($F15/10000*Model!H49/Model!H61-K$13/10000*Model!H56/Model!H61)*(1-Model!H44))-$B$9)/($B$8-$B$9)*$B$16 -> 197.31424
A16: ABVPS Sep-27E (Rs) = average | B16: =AVERAGE(B14,B15) -> 185.33716 | F16: -10 | G16: =(($B$12+($F16/10000*Model!H49/Model!H61-G$13/10000*Model!H56/Model!H61)*(1-Model!H44))-$B$9)/($B$8-$B$9)*$B$16 -> 314.85207 | H16: =(($B$12+($F16/10000*Model!H49/Model!H61-H$13/10000*Model!H56/Model!H61)*(1-Model!H44))-$B$9)/($B$8-$B$9)*$B$16 -> 296.16454 | I16: =(($B$12+($F16/10000*Model!H49/Model!H61-I$13/10000*Model!H56/Model!H61)*(1-Model!H44))-$B$9)/($B$8-$B$9)*$B$16 -> 277.477 | J16: =(($B$12+($F16/10000*Model!H49/Model!H61-J$13/10000*Model!H56/Model!H61)*(1-Model!H44))-$B$9)/($B$8-$B$9)*$B$16 -> 249.44571 | K16: =(($B$12+($F16/10000*Model!H49/Model!H61-K$13/10000*Model!H56/Model!H61)*(1-Model!H44))-$B$9)/($B$8-$B$9)*$B$16 -> 221.41441
A17: Fair value - P/ABV method (Rs) | B17: =B13*B16 -> 301.57717 | F17: 0 | G17: =(($B$12+($F17/10000*Model!H49/Model!H61-G$13/10000*Model!H56/Model!H61)*(1-Model!H44))-$B$9)/($B$8-$B$9)*$B$16 -> 338.95223 | H17: =(($B$12+($F17/10000*Model!H49/Model!H61-H$13/10000*Model!H56/Model!H61)*(1-Model!H44))-$B$9)/($B$8-$B$9)*$B$16 -> 320.2647 | I17: =(($B$12+($F17/10000*Model!H49/Model!H61-I$13/10000*Model!H56/Model!H61)*(1-Model!H44))-$B$9)/($B$8-$B$9)*$B$16 -> 301.57717 | J17: =(($B$12+($F17/10000*Model!H49/Model!H61-J$13/10000*Model!H56/Model!H61)*(1-Model!H44))-$B$9)/($B$8-$B$9)*$B$16 -> 273.54587 | K17: =(($B$12+($F17/10000*Model!H49/Model!H61-K$13/10000*Model!H56/Model!H61)*(1-Model!H44))-$B$9)/($B$8-$B$9)*$B$16 -> 245.51457
F18: 10 | G18: =(($B$12+($F18/10000*Model!H49/Model!H61-G$13/10000*Model!H56/Model!H61)*(1-Model!H44))-$B$9)/($B$8-$B$9)*$B$16 -> 363.0524 | H18: =(($B$12+($F18/10000*Model!H49/Model!H61-H$13/10000*Model!H56/Model!H61)*(1-Model!H44))-$B$9)/($B$8-$B$9)*$B$16 -> 344.36486 | I18: =(($B$12+($F18/10000*Model!H49/Model!H61-I$13/10000*Model!H56/Model!H61)*(1-Model!H44))-$B$9)/($B$8-$B$9)*$B$16 -> 325.67733 | J18: =(($B$12+($F18/10000*Model!H49/Model!H61-J$13/10000*Model!H56/Model!H61)*(1-Model!H44))-$B$9)/($B$8-$B$9)*$B$16 -> 297.64604 | K18: =(($B$12+($F18/10000*Model!H49/Model!H61-K$13/10000*Model!H56/Model!H61)*(1-Model!H44))-$B$9)/($B$8-$B$9)*$B$16 -> 269.61474
A19: METHOD 2: Residual income (RI) model | F19: 20 | G19: =(($B$12+($F19/10000*Model!H49/Model!H61-G$13/10000*Model!H56/Model!H61)*(1-Model!H44))-$B$9)/($B$8-$B$9)*$B$16 -> 387.15256 | H19: =(($B$12+($F19/10000*Model!H49/Model!H61-H$13/10000*Model!H56/Model!H61)*(1-Model!H44))-$B$9)/($B$8-$B$9)*$B$16 -> 368.46503 | I19: =(($B$12+($F19/10000*Model!H49/Model!H61-I$13/10000*Model!H56/Model!H61)*(1-Model!H44))-$B$9)/($B$8-$B$9)*$B$16 -> 349.7775 | J19: =(($B$12+($F19/10000*Model!H49/Model!H61-J$13/10000*Model!H56/Model!H61)*(1-Model!H44))-$B$9)/($B$8-$B$9)*$B$16 -> 321.7462 | K19: =(($B$12+($F19/10000*Model!H49/Model!H61-K$13/10000*Model!H56/Model!H61)*(1-Model!H44))-$B$9)/($B$8-$B$9)*$B$16 -> 293.7149
B20: FY27E | C20: FY28E | D20: FY29E
A21: Opening BVPS (Rs) | B21: =Model!F72 -> 146.19689 | C21: =Model!G72 -> 174.07915 | D21: =Model!H72 -> 203.11822 | F21: SCENARIOS (values captured by running the model with switch = 1, 2, 3 on Model!B3)
A22: ROE | B22: =Model!G62 -> 0.19345991 | C22: =Model!H62 -> 0.17108092 | D22: =Model!I62 -> 0.16489157 | F22: Scenario | G22: Probability | H22: FY28E ROE | I22: FY28E EPS | J22: Target (Rs) | K22: Upside
A23: Residual income = (ROE - Ke) x opening BV | B23: =(B22-$B$8)*B21 -> 8.4004604 | C23: =(C22-$B$8)*C21 -> 6.1068573 | D23: =(D22-$B$8)*D21 -> 5.8684043 | F23: Bear | G23: 0.25 | H23: 0.13507537 | I23: 24.196177 | J23: 158.57932 | K23: -0.51206364
A24: Discount factor at Ke (from Mar-26) | B24: =1/(1+$B$8)^1 -> 0.88028169 | C24: =1/(1+$B$8)^2 -> 0.77489585 | D24: =1/(1+$B$8)^3 -> 0.68212663 | F24: Base | G24: 0.5 | H24: 0.17108092 | I24: 32.265637 | J24: 300.07135 | K24: -0.076703547
A25: PV of residual income | B25: =B23*B24 -> 7.3947715 | C25: =C23*C24 -> 4.7321784 | D25: =D23*D24 -> 4.0029949 | F25: Bull | G25: 0.25 | H25: 0.18799392 | I25: 36.332516 | J25: 371.94441 | K25: 0.14444435
A26: Long-run RI growth (= g, consistent with Method 1; lower it to model ROE fade) | B26: =B9 -> 0.085 | F26: Probability-weighted | J26: =SUMPRODUCT(G23:G25,J23:J25) -> 282.66661 | K26: =J26/B4-1 -> -0.1302566
A27: Terminal value of RI (at FY29E) | B27: =D23*(1+B26)/(B8-B26) -> 124.84743 | F27: Scenario values are pasted from runs of the switch at Model!B3 (re-run after changing inputs).
A28: PV of terminal value | B28: =B27*D24 -> 85.161754
A29: Value at Mar-26 = BV0 + PV(RI) + PV(TV) | B29: =B21+SUM(B25:D25)+B28 -> 247.48859
A30: Value today (Sep-26) = x (1+Ke)^0.5 | B30: =B29*(1+B8)^0.5 -> 263.78151
A31: 12-month fair value = today x (1+Ke) - DPS FY27E | B31: =B30*(1+B8)-Model!G74 -> 296.55776
A33: BLENDED TARGET
A34: Weight: P/ABV method | B34: 0.7
A35: Weight: RI method | B35: =1-B34 -> 0.3
A36: 12-month target price (Rs) | B36: =B34*B17+B35*B31 -> 300.07135
A37: Upside / (downside) vs CMP | B37: =B36/B4-1 -> -0.076703547
A38: Rating (BUY >+15%; HOLD -10% to +15%; SELL <-10%) | B38: =IF(B37>0.15,"BUY",IF(B37>-0.1,"HOLD","SELL")) -> HOLD
A40: MULTIPLES CHECK
A41: P/BV on FY26 book (current) | B41: =B4/Model!F72 -> 2.2230295
A42: P/ABV on Sep-27E (current) | B42: =B4/B16 -> 1.7535609
A43: P/E on FY27E EPS (current) | B43: =B4/Model!G71 -> 10.490542
...

Sheet Quarterly
A1: KVB - quarterly results tracker (source: Screener / company filings; standalone)
A3: INR crore | B3: Jun-23 | C3: Sep-23 | D3: Dec-23 | E3: Mar-24 | F3: Jun-24 | G3: Sep-24 | H3: Dec-24 | I3: Mar-25 | J3: Jun-25 | K3: Sep-25 | L3: Dec-25 | M3: Mar-26 | N3: Jun-26
A4: Interest earned | B4: 1883 | C4: 1997 | D4: 2139 | E4: 2187 | F4: 2285 | G4: 2387 | H4: 2489 | I4: 2516 | J4: 2569 | K4: 2808 | L4: 2794 | M4: 2904 | N4: 3049
A5: Interest expended | B5: 986 | C5: 1082 | D5: 1138 | E5: 1189 | F5: 1260 | G5: 1324 | H5: 1407 | I5: 1427 | J5: 1489 | K5: 1547 | L5: 1555 | M5: 1545 | N5: 1627
A6: Opex + provisions | B6: 741 | C6: 743 | D6: 833 | E6: 1051 | F6: 800 | G6: 896 | H6: 878 | I6: 925 | J6: 839 | K6: 1030 | L6: 848 | M6: 985 | N6: 859
A7: Other income | B7: 333 | C7: 339 | D7: 358 | E7: 626 | F7: 388 | G7: 469 | H7: 465 | I7: 509 | J7: 447 | K7: 512 | L7: 509 | M7: 616 | N7: 442
A8: Net profit | B8: 359 | C8: 378 | D8: 412 | E8: 456 | F8: 459 | G8: 474 | H8: 496 | I8: 513 | J8: 521 | K8: 574 | L8: 690 | M8: 725 | N8: 756
A9: Gross NPA % | B9: 0.0199 | C9: 0.0173 | D9: 0.0158 | E9: 0.014 | F9: 0.0132 | G9: 0.011 | H9: 0.0083 | I9: 0.0076 | J9: 0.0066 | K9: 0.0076 | L9: 0.0071 | M9: 0.0075 | N9: 0.0074
A10: Net NPA % | B10: 0.0059 | C10: 0.0047 | D10: 0.0042 | E10: 0.004 | F10: 0.0038 | G10: 0.0028 | H10: 0.002 | I10: 0.002 | J10: 0.0019 | K10: 0.0019 | L10: 0.0019 | M10: 0.0019 | N10: 0.0019
A11: NII (screener basis) | B11: =B4-B5 -> 897 | C11: =C4-C5 -> 915 | D11: =D4-D5 -> 1001 | E11: =E4-E5 -> 998 | F11: =F4-F5 -> 1025 | G11: =G4-G5 -> 1063 | H11: =H4-H5 -> 1082 | I11: =I4-I5 -> 1089 | ... N11: =N4-N5 -> 1422
A12: PBT | B12: =B4-B5-B6+B7 -> 489 | C12: =C4-C5-C6+C7 -> 511 | D12: =D4-D5-D6+D7 -> 526 | E12: =E4-E5-E6+E7 -> 573 | F12: =F4-F5-F6+F7 -> 613 | G12: =G4-G5-G6+G7 -> 636 | H12: =H4-H5-H6+H7 -> 669 | I12: =I4-I5-I6+I7 -> 673 | ... N12: =N4-N5-N6+N7 -> 1005
A13: NII growth YoY | F13: =F11/B11-1 -> 0.14269788 | G13: =G11/C11-1 -> 0.16174863 | H13: =H11/D11-1 -> 0.080919081 | I13: =I11/E11-1 -> 0.091182365 | J13: =J11/F11-1 -> 0.053658537 | K13: =K11/G11-1 -> 0.18626529 | L13: =L11/H11-1 -> 0.14510166 | M13: =M11/I11-1 -> 0.24793388 | N13: =N11/J11-1 -> 0.31666667
A14: Net profit growth YoY | F14: =F8/B8-1 -> 0.27855153 | G14: =G8/C8-1 -> 0.25396825 | H14: =H8/D8-1 -> 0.2038835 | I14: =I8/E8-1 -> 0.125 | J14: =J8/F8-1 -> 0.13507625 | K14: =K8/G8-1 -> 0.21097046 | L14: =L8/H8-1 -> 0.39112903 | M14: =M8/I8-1 -> 0.41325536 | N14: =N8/J8-1 -> 0.45105566
A16: Note: company-reported NII for Q1FY27 was Rs1,500cr (NIM 4.26%) vs Rs1,422cr here; Screener classifies some interest items as other income. PBT/PAT tie exactly. Next result: 15-Oct-2026.

Sheet Peers
A1: Private-sector bank comps (Screener industry table + company pages, 30-Sep-2026; consolidated where shown)
A3: Bank | B3: CMP (Rs) | C3: P/E (TTM) | D3: Mkt cap (Rs cr) | E3: Div yld % | F3: PAT Q1FY27 | G3: PAT YoY % | H3: Int. earned Q1FY27 | I3: Int. earned YoY % | J3: Book value/sh | K3: ROE % | L3: P/B
A4: HDFC Bank | B4: 720 | C4: 14.06 | D4: 1110447.9 | E4: 1.81 | F4: 20382.69 | G4: 18.37 | H4: 90575.33 | I4: 3.67 | J4: 390 | K4: 13.6 | L4: =IF(ISNUMBER(J4),B4/J4,"") -> 1.8461538
A5: ICICI Bank | B5: 1292.6 | C5: 16.56 | D5: 928459.56 | E5: 0.93 | F5: 16276.22 | G5: 13.88 | H5: 52240.85 | I5: 6.44 | L5: =IF(ISNUMBER(J5),B5/J5,"")
A6: Kotak Mahindra Bank | B6: 406 | C6: 20.14 | D6: 403422.74 | E6: 0.16 | F6: 5480.46 | G6: 22.55 | H6: 18354.57 | I6: 6.41 | L6: =IF(ISNUMBER(J6),B6/J6,"")
A7: Axis Bank | B7: 1209 | C7: 13.55 | D7: 376089.13 | E7: 0.08 | F7: 7670.37 | G7: 22.24 | H7: 35541.96 | I7: 9.87 | L7: =IF(ISNUMBER(J7),B7/J7,"")
A8: IDBI Bank | B8: 83.18 | C8: 9.59 | D8: 89427.88 | E8: 2.52 | F8: 2130.57 | G8: 5.35 | H8: 7549.28 | I8: 7.44 | L8: =IF(ISNUMBER(J8),B8/J8,"")
A9: Federal Bank | B9: 320.7 | C9: 16.98 | D9: 79479.71 | E9: 0.37 | F9: 1302.49 | G9: 36.78 | H9: 7861.58 | I9: 9.94 | J9: 162 | K9: 11.6 | L9: =IF(ISNUMBER(J9),B9/J9,"") -> 1.9796296
A10: IndusInd Bank | B10: 885 | C10: 52.25 | D10: 69094.81 | E10: 0.17 | F10: 1037.05 | G10: 71.68 | H10: 11309.94 | I10: -7.78 | L10: =IF(ISNUMBER(J10),B10/J10,"")
A11: IDFC First Bank | B11: 79.46 | C11: 30.45 | D11: 68482.96 | E11: 0.31 | F11: 1074.96 | G11: 132.39 | H11: 11051.09 | I11: 14.61 | L11: =IF(ISNUMBER(J11),B11/J11,"")
A12: Yes Bank | B12: 20.71 | C12: 17.2 | D12: 64944.15 | E12: 0 | F12: 1071.81 | G12: 32.54 | H12: 8054.49 | I12: 5.92 | L12: =IF(ISNUMBER(J12),B12/J12,"")
A13: RBL Bank | B13: 402 | C13: 71.47 | D13: 62591.33 | E13: 0.25 | F13: 253.7 | G13: 26.64 | H13: 3840.25 | I13: 11.6 | L13: =IF(ISNUMBER(J13),B13/J13,"")
A14: Karur Vysya Bank | B14: 318.8 | C14: 11.22 | D14: 30808.88 | E14: 0.82 | F14: 755.7 | G14: 44.92 | H14: 3049.42 | I14: 18.72 | J14: 146 | K14: 19.1 | L14: =IF(ISNUMBER(J14),B14/J14,"") -> 2.1835616
A15: Bandhan Bank | B15: 185.31 | C15: 22 | D15: 29773.93 | E15: 0.81 | F15: 501.67 | G15: 34.87 | H15: 5630.55 | I15: 2.83 | L15: =IF(ISNUMBER(J15),B15/J15,"")
A16: City Union Bank | B16: 214.85 | C16: 15.18 | D16: 21286.08 | E16: 0.93 | F16: 382.57 | G16: 25.06 | H16: 1984.99 | I16: 23.65 | L16: =IF(ISNUMBER(J16),B16/J16,"")
A17: J&K Bank | B17: 138.4 | C17: 6.61 | D17: 15240.37 | E17: 1.55 | F17: 428.8 | G17: -11.5 | H17: 3547.48 | I17: 8.5 | L17: =IF(ISNUMBER(J17),B17/J17,"")
A18: Tamilnad Mercantile Bank | B18: 863.55 | C18: 9.46 | D18: 13662.55 | E18: 1.45 | F18: 411.51 | G18: 34.97 | H18: 1662.43 | I18: 19.92 | L18: =IF(ISNUMBER(J18),B18/J18,"")
A19: South Indian Bank | B19: 48.72 | C19: 8.44 | D19: 12756.98 | E19: 0.92 | F19: 377.63 | G19: 17.29 | H19: 2627.81 | I19: 11.23 | L19: =IF(ISNUMBER(J19),B19/J19,"")
A20: Karnataka Bank | B20: 322.75 | C20: 8.49 | D20: 12204.86 | E20: 1.55 | F20: 418.95 | G20: 43.28 | H20: 2382.65 | I20: 5.37 | L20: =IF(ISNUMBER(J20),B20/J20,"")
A21: DCB Bank | B21: 202.2 | C21: 8.27 | D21: 6517.91 | E21: 0.72 | F21: 213.2 | G21: 35.57 | H21: 1984.31 | I21: 9.41 | L21: =IF(ISNUMBER(J21),B21/J21,"")
A22: CSB Bank | B22: 316.2 | C22: 8.23 | D22: 5468.73 | E22: 0 | F22: 150.04 | G22: 26.51 | H22: 1287.32 | I22: 23.67 | L22: =IF(ISNUMBER(J22),B22/J22,"")
A23: Dhanlaxmi Bank | B23: 28.1 | C23: 9.56 | D23: 1104.01 | E23: 0 | F23: 24.91 | G23: 104.52 | H23: 449.36 | I23: 22.19 | L23: =IF(ISNUMBER(J23),B23/J23,"")
A25: Median - all 20 banks | C25: =MEDIAN(C4:C23) -> 13.805
A26: Median - mid/small (mkt cap < Rs35,000 cr) | C26: =MEDIAN(C14:C23) -> 8.975
A27: KVB P/E premium/(discount) to mid/small median | C27: =C14/C26-1 -> 0.25013928
A29: Book value & ROE filled for 3 banks (company pages). EXERCISE: fill J:K for the rest from each Screener page, then run p3 comps tool for the P/B-vs-ROE regression.
